2023-11-06 19:26:24 ERROR 400 response executing GraphQL.
2023-11-06 19:26:24 ERROR {"errors":[{"message":"Invalid configuration for hyperparameter 'learning_rate'","path":["upsertSweep"]}],"data":{"upsertSweep":null}}
2023-11-06 19:26:24 ERROR Traceback (most recent call last):
  File "/Users/michalchrzanowski/anaconda3/envs/ML_M1/lib/python3.9/site-packages/wandb/sdk/lib/retry.py", line 131, in __call__
    result = self._call_fn(*args, **kwargs)
  File "/Users/michalchrzanowski/anaconda3/envs/ML_M1/lib/python3.9/site-packages/wandb/sdk/internal/internal_api.py", line 366, in execute
    return self.client.execute(*args, **kwargs)  # type: ignore
  File "/Users/michalchrzanowski/anaconda3/envs/ML_M1/lib/python3.9/site-packages/wandb/vendor/gql-0.2.0/wandb_gql/client.py", line 52, in execute
    result = self._get_result(document, *args, **kwargs)
  File "/Users/michalchrzanowski/anaconda3/envs/ML_M1/lib/python3.9/site-packages/wandb/vendor/gql-0.2.0/wandb_gql/client.py", line 60, in _get_result
    return self.transport.execute(document, *args, **kwargs)
  File "/Users/michalchrzanowski/anaconda3/envs/ML_M1/lib/python3.9/site-packages/wandb/sdk/lib/gql_request.py", line 59, in execute
    request.raise_for_status()
  File "/Users/michalchrzanowski/anaconda3/envs/ML_M1/lib/python3.9/site-packages/requests/models.py", line 1021, in raise_for_status
    raise HTTPError(http_error_msg, response=self)
requests.exceptions.HTTPError: 400 Client Error: Bad Request for url: https://api.wandb.ai/graphql

During handling of the above exception, another exception occurred:

Traceback (most recent call last):
  File "/Users/michalchrzanowski/anaconda3/envs/ML_M1/lib/python3.9/site-packages/wandb/cli/cli.py", line 102, in wrapper
    return func(*args, **kwargs)
  File "/Users/michalchrzanowski/anaconda3/envs/ML_M1/lib/python3.9/site-packages/wandb/cli/cli.py", line 841, in sweep
    sweep_id, warnings = api.upsert_sweep(
  File "/Users/michalchrzanowski/anaconda3/envs/ML_M1/lib/python3.9/site-packages/wandb/apis/internal.py", line 129, in upsert_sweep
    return self.api.upsert_sweep(*args, **kwargs)
  File "/Users/michalchrzanowski/anaconda3/envs/ML_M1/lib/python3.9/site-packages/wandb/apis/normalize.py", line 73, in wrapper
    raise err
  File "/Users/michalchrzanowski/anaconda3/envs/ML_M1/lib/python3.9/site-packages/wandb/apis/normalize.py", line 41, in wrapper
    return func(*args, **kwargs)
  File "/Users/michalchrzanowski/anaconda3/envs/ML_M1/lib/python3.9/site-packages/wandb/sdk/internal/internal_api.py", line 2960, in upsert_sweep
    raise e
  File "/Users/michalchrzanowski/anaconda3/envs/ML_M1/lib/python3.9/site-packages/wandb/sdk/internal/internal_api.py", line 2954, in upsert_sweep
    response = self.gql(
  File "/Users/michalchrzanowski/anaconda3/envs/ML_M1/lib/python3.9/site-packages/wandb/sdk/internal/internal_api.py", line 338, in gql
    ret = self._retry_gql(
  File "/Users/michalchrzanowski/anaconda3/envs/ML_M1/lib/python3.9/site-packages/wandb/sdk/lib/retry.py", line 147, in __call__
    retry_timedelta_triggered = check_retry_fn(e)
  File "/Users/michalchrzanowski/anaconda3/envs/ML_M1/lib/python3.9/site-packages/wandb/util.py", line 877, in no_retry_4xx
    raise UsageError(body["errors"][0]["message"])
wandb.errors.UsageError: Invalid configuration for hyperparameter 'learning_rate'

2023-11-06 19:26:55 ERROR 400 response executing GraphQL.
2023-11-06 19:26:55 ERROR {"errors":[{"message":"Invalid configuration for hyperparameter '_learning_rate'","path":["upsertSweep"]}],"data":{"upsertSweep":null}}
2023-11-06 19:26:55 ERROR Traceback (most recent call last):
  File "/Users/michalchrzanowski/anaconda3/envs/ML_M1/lib/python3.9/site-packages/wandb/sdk/lib/retry.py", line 131, in __call__
    result = self._call_fn(*args, **kwargs)
  File "/Users/michalchrzanowski/anaconda3/envs/ML_M1/lib/python3.9/site-packages/wandb/sdk/internal/internal_api.py", line 366, in execute
    return self.client.execute(*args, **kwargs)  # type: ignore
  File "/Users/michalchrzanowski/anaconda3/envs/ML_M1/lib/python3.9/site-packages/wandb/vendor/gql-0.2.0/wandb_gql/client.py", line 52, in execute
    result = self._get_result(document, *args, **kwargs)
  File "/Users/michalchrzanowski/anaconda3/envs/ML_M1/lib/python3.9/site-packages/wandb/vendor/gql-0.2.0/wandb_gql/client.py", line 60, in _get_result
    return self.transport.execute(document, *args, **kwargs)
  File "/Users/michalchrzanowski/anaconda3/envs/ML_M1/lib/python3.9/site-packages/wandb/sdk/lib/gql_request.py", line 59, in execute
    request.raise_for_status()
  File "/Users/michalchrzanowski/anaconda3/envs/ML_M1/lib/python3.9/site-packages/requests/models.py", line 1021, in raise_for_status
    raise HTTPError(http_error_msg, response=self)
requests.exceptions.HTTPError: 400 Client Error: Bad Request for url: https://api.wandb.ai/graphql

During handling of the above exception, another exception occurred:

Traceback (most recent call last):
  File "/Users/michalchrzanowski/anaconda3/envs/ML_M1/lib/python3.9/site-packages/wandb/cli/cli.py", line 102, in wrapper
    return func(*args, **kwargs)
  File "/Users/michalchrzanowski/anaconda3/envs/ML_M1/lib/python3.9/site-packages/wandb/cli/cli.py", line 841, in sweep
    sweep_id, warnings = api.upsert_sweep(
  File "/Users/michalchrzanowski/anaconda3/envs/ML_M1/lib/python3.9/site-packages/wandb/apis/internal.py", line 129, in upsert_sweep
    return self.api.upsert_sweep(*args, **kwargs)
  File "/Users/michalchrzanowski/anaconda3/envs/ML_M1/lib/python3.9/site-packages/wandb/apis/normalize.py", line 73, in wrapper
    raise err
  File "/Users/michalchrzanowski/anaconda3/envs/ML_M1/lib/python3.9/site-packages/wandb/apis/normalize.py", line 41, in wrapper
    return func(*args, **kwargs)
  File "/Users/michalchrzanowski/anaconda3/envs/ML_M1/lib/python3.9/site-packages/wandb/sdk/internal/internal_api.py", line 2960, in upsert_sweep
    raise e
  File "/Users/michalchrzanowski/anaconda3/envs/ML_M1/lib/python3.9/site-packages/wandb/sdk/internal/internal_api.py", line 2954, in upsert_sweep
    response = self.gql(
  File "/Users/michalchrzanowski/anaconda3/envs/ML_M1/lib/python3.9/site-packages/wandb/sdk/internal/internal_api.py", line 338, in gql
    ret = self._retry_gql(
  File "/Users/michalchrzanowski/anaconda3/envs/ML_M1/lib/python3.9/site-packages/wandb/sdk/lib/retry.py", line 147, in __call__
    retry_timedelta_triggered = check_retry_fn(e)
  File "/Users/michalchrzanowski/anaconda3/envs/ML_M1/lib/python3.9/site-packages/wandb/util.py", line 877, in no_retry_4xx
    raise UsageError(body["errors"][0]["message"])
wandb.errors.UsageError: Invalid configuration for hyperparameter '_learning_rate'

2023-11-06 19:28:37 ERROR 400 response executing GraphQL.
2023-11-06 19:28:37 ERROR {"errors":[{"message":"Invalid configuration for hyperparameter 'learning_rate'","path":["upsertSweep"]}],"data":{"upsertSweep":null}}
2023-11-06 19:28:37 ERROR Traceback (most recent call last):
  File "/Users/michalchrzanowski/anaconda3/envs/ML_M1/lib/python3.9/site-packages/wandb/sdk/lib/retry.py", line 131, in __call__
    result = self._call_fn(*args, **kwargs)
  File "/Users/michalchrzanowski/anaconda3/envs/ML_M1/lib/python3.9/site-packages/wandb/sdk/internal/internal_api.py", line 366, in execute
    return self.client.execute(*args, **kwargs)  # type: ignore
  File "/Users/michalchrzanowski/anaconda3/envs/ML_M1/lib/python3.9/site-packages/wandb/vendor/gql-0.2.0/wandb_gql/client.py", line 52, in execute
    result = self._get_result(document, *args, **kwargs)
  File "/Users/michalchrzanowski/anaconda3/envs/ML_M1/lib/python3.9/site-packages/wandb/vendor/gql-0.2.0/wandb_gql/client.py", line 60, in _get_result
    return self.transport.execute(document, *args, **kwargs)
  File "/Users/michalchrzanowski/anaconda3/envs/ML_M1/lib/python3.9/site-packages/wandb/sdk/lib/gql_request.py", line 59, in execute
    request.raise_for_status()
  File "/Users/michalchrzanowski/anaconda3/envs/ML_M1/lib/python3.9/site-packages/requests/models.py", line 1021, in raise_for_status
    raise HTTPError(http_error_msg, response=self)
requests.exceptions.HTTPError: 400 Client Error: Bad Request for url: https://api.wandb.ai/graphql

During handling of the above exception, another exception occurred:

Traceback (most recent call last):
  File "/Users/michalchrzanowski/anaconda3/envs/ML_M1/lib/python3.9/site-packages/wandb/cli/cli.py", line 102, in wrapper
    return func(*args, **kwargs)
  File "/Users/michalchrzanowski/anaconda3/envs/ML_M1/lib/python3.9/site-packages/wandb/cli/cli.py", line 841, in sweep
    sweep_id, warnings = api.upsert_sweep(
  File "/Users/michalchrzanowski/anaconda3/envs/ML_M1/lib/python3.9/site-packages/wandb/apis/internal.py", line 129, in upsert_sweep
    return self.api.upsert_sweep(*args, **kwargs)
  File "/Users/michalchrzanowski/anaconda3/envs/ML_M1/lib/python3.9/site-packages/wandb/apis/normalize.py", line 73, in wrapper
    raise err
  File "/Users/michalchrzanowski/anaconda3/envs/ML_M1/lib/python3.9/site-packages/wandb/apis/normalize.py", line 41, in wrapper
    return func(*args, **kwargs)
  File "/Users/michalchrzanowski/anaconda3/envs/ML_M1/lib/python3.9/site-packages/wandb/sdk/internal/internal_api.py", line 2960, in upsert_sweep
    raise e
  File "/Users/michalchrzanowski/anaconda3/envs/ML_M1/lib/python3.9/site-packages/wandb/sdk/internal/internal_api.py", line 2954, in upsert_sweep
    response = self.gql(
  File "/Users/michalchrzanowski/anaconda3/envs/ML_M1/lib/python3.9/site-packages/wandb/sdk/internal/internal_api.py", line 338, in gql
    ret = self._retry_gql(
  File "/Users/michalchrzanowski/anaconda3/envs/ML_M1/lib/python3.9/site-packages/wandb/sdk/lib/retry.py", line 147, in __call__
    retry_timedelta_triggered = check_retry_fn(e)
  File "/Users/michalchrzanowski/anaconda3/envs/ML_M1/lib/python3.9/site-packages/wandb/util.py", line 877, in no_retry_4xx
    raise UsageError(body["errors"][0]["message"])
wandb.errors.UsageError: Invalid configuration for hyperparameter 'learning_rate'

2023-11-06 19:32:36 ERROR 400 response executing GraphQL.
2023-11-06 19:32:36 ERROR {"errors":[{"message":"name required for project query","path":["project"]}],"data":{"project":null}}
2023-11-06 19:32:36 ERROR Traceback (most recent call last):
  File "/Users/michalchrzanowski/anaconda3/envs/ML_M1/lib/python3.9/site-packages/wandb/apis/normalize.py", line 41, in wrapper
    return func(*args, **kwargs)
  File "/Users/michalchrzanowski/anaconda3/envs/ML_M1/lib/python3.9/site-packages/wandb/sdk/internal/internal_api.py", line 1001, in sweep
    response = self.gql(
  File "/Users/michalchrzanowski/anaconda3/envs/ML_M1/lib/python3.9/site-packages/wandb/sdk/internal/internal_api.py", line 338, in gql
    ret = self._retry_gql(
  File "/Users/michalchrzanowski/anaconda3/envs/ML_M1/lib/python3.9/site-packages/wandb/sdk/lib/retry.py", line 131, in __call__
    result = self._call_fn(*args, **kwargs)
  File "/Users/michalchrzanowski/anaconda3/envs/ML_M1/lib/python3.9/site-packages/wandb/sdk/internal/internal_api.py", line 366, in execute
    return self.client.execute(*args, **kwargs)  # type: ignore
  File "/Users/michalchrzanowski/anaconda3/envs/ML_M1/lib/python3.9/site-packages/wandb/vendor/gql-0.2.0/wandb_gql/client.py", line 52, in execute
    result = self._get_result(document, *args, **kwargs)
  File "/Users/michalchrzanowski/anaconda3/envs/ML_M1/lib/python3.9/site-packages/wandb/vendor/gql-0.2.0/wandb_gql/client.py", line 60, in _get_result
    return self.transport.execute(document, *args, **kwargs)
  File "/Users/michalchrzanowski/anaconda3/envs/ML_M1/lib/python3.9/site-packages/wandb/sdk/lib/gql_request.py", line 59, in execute
    request.raise_for_status()
  File "/Users/michalchrzanowski/anaconda3/envs/ML_M1/lib/python3.9/site-packages/requests/models.py", line 1021, in raise_for_status
    raise HTTPError(http_error_msg, response=self)
requests.exceptions.HTTPError: 400 Client Error: Bad Request for url: https://api.wandb.ai/graphql

During handling of the above exception, another exception occurred:

Traceback (most recent call last):
  File "/Users/michalchrzanowski/anaconda3/envs/ML_M1/lib/python3.9/site-packages/wandb/cli/cli.py", line 102, in wrapper
    return func(*args, **kwargs)
  File "/Users/michalchrzanowski/anaconda3/envs/ML_M1/lib/python3.9/site-packages/wandb/cli/cli.py", line 1496, in agent
    wandb_agent.agent(sweep_id, entity=entity, project=project, count=count)
  File "/Users/michalchrzanowski/anaconda3/envs/ML_M1/lib/python3.9/site-packages/wandb/wandb_agent.py", line 583, in agent
    return run_agent(
  File "/Users/michalchrzanowski/anaconda3/envs/ML_M1/lib/python3.9/site-packages/wandb/wandb_agent.py", line 528, in run_agent
    agent.run()
  File "/Users/michalchrzanowski/anaconda3/envs/ML_M1/lib/python3.9/site-packages/wandb/wandb_agent.py", line 190, in run
    sweep_obj = self._api.sweep(self._sweep_id, "{}")
  File "/Users/michalchrzanowski/anaconda3/envs/ML_M1/lib/python3.9/site-packages/wandb/apis/internal.py", line 126, in sweep
    return self.api.sweep(*args, **kwargs)
  File "/Users/michalchrzanowski/anaconda3/envs/ML_M1/lib/python3.9/site-packages/wandb/apis/normalize.py", line 51, in wrapper
    raise CommError(message, error)
wandb.errors.CommError: name required for project query (Error 400: Bad Request)

2023-11-06 19:33:42 ERROR 400 response executing GraphQL.
2023-11-06 19:33:42 ERROR {"errors":[{"message":"name required for project query","path":["project"]}],"data":{"project":null}}
2023-11-06 19:33:42 ERROR Traceback (most recent call last):
  File "/Users/michalchrzanowski/anaconda3/envs/ML_M1/lib/python3.9/site-packages/wandb/apis/normalize.py", line 41, in wrapper
    return func(*args, **kwargs)
  File "/Users/michalchrzanowski/anaconda3/envs/ML_M1/lib/python3.9/site-packages/wandb/sdk/internal/internal_api.py", line 1001, in sweep
    response = self.gql(
  File "/Users/michalchrzanowski/anaconda3/envs/ML_M1/lib/python3.9/site-packages/wandb/sdk/internal/internal_api.py", line 338, in gql
    ret = self._retry_gql(
  File "/Users/michalchrzanowski/anaconda3/envs/ML_M1/lib/python3.9/site-packages/wandb/sdk/lib/retry.py", line 131, in __call__
    result = self._call_fn(*args, **kwargs)
  File "/Users/michalchrzanowski/anaconda3/envs/ML_M1/lib/python3.9/site-packages/wandb/sdk/internal/internal_api.py", line 366, in execute
    return self.client.execute(*args, **kwargs)  # type: ignore
  File "/Users/michalchrzanowski/anaconda3/envs/ML_M1/lib/python3.9/site-packages/wandb/vendor/gql-0.2.0/wandb_gql/client.py", line 52, in execute
    result = self._get_result(document, *args, **kwargs)
  File "/Users/michalchrzanowski/anaconda3/envs/ML_M1/lib/python3.9/site-packages/wandb/vendor/gql-0.2.0/wandb_gql/client.py", line 60, in _get_result
    return self.transport.execute(document, *args, **kwargs)
  File "/Users/michalchrzanowski/anaconda3/envs/ML_M1/lib/python3.9/site-packages/wandb/sdk/lib/gql_request.py", line 59, in execute
    request.raise_for_status()
  File "/Users/michalchrzanowski/anaconda3/envs/ML_M1/lib/python3.9/site-packages/requests/models.py", line 1021, in raise_for_status
    raise HTTPError(http_error_msg, response=self)
requests.exceptions.HTTPError: 400 Client Error: Bad Request for url: https://api.wandb.ai/graphql

During handling of the above exception, another exception occurred:

Traceback (most recent call last):
  File "/Users/michalchrzanowski/anaconda3/envs/ML_M1/lib/python3.9/site-packages/wandb/cli/cli.py", line 102, in wrapper
    return func(*args, **kwargs)
  File "/Users/michalchrzanowski/anaconda3/envs/ML_M1/lib/python3.9/site-packages/wandb/cli/cli.py", line 1496, in agent
    wandb_agent.agent(sweep_id, entity=entity, project=project, count=count)
  File "/Users/michalchrzanowski/anaconda3/envs/ML_M1/lib/python3.9/site-packages/wandb/wandb_agent.py", line 583, in agent
    return run_agent(
  File "/Users/michalchrzanowski/anaconda3/envs/ML_M1/lib/python3.9/site-packages/wandb/wandb_agent.py", line 528, in run_agent
    agent.run()
  File "/Users/michalchrzanowski/anaconda3/envs/ML_M1/lib/python3.9/site-packages/wandb/wandb_agent.py", line 190, in run
    sweep_obj = self._api.sweep(self._sweep_id, "{}")
  File "/Users/michalchrzanowski/anaconda3/envs/ML_M1/lib/python3.9/site-packages/wandb/apis/internal.py", line 126, in sweep
    return self.api.sweep(*args, **kwargs)
  File "/Users/michalchrzanowski/anaconda3/envs/ML_M1/lib/python3.9/site-packages/wandb/apis/normalize.py", line 51, in wrapper
    raise CommError(message, error)
wandb.errors.CommError: name required for project query (Error 400: Bad Request)

2023-11-06 19:56:17 ERROR 400 response executing GraphQL.
2023-11-06 19:56:17 ERROR {"errors":[{"message":"entityName required for project query","path":["project"]}],"data":{"project":null}}
2023-11-06 19:56:17 ERROR Traceback (most recent call last):
  File "/Users/michalchrzanowski/anaconda3/envs/ML_M1/lib/python3.9/site-packages/wandb/apis/normalize.py", line 41, in wrapper
    return func(*args, **kwargs)
  File "/Users/michalchrzanowski/anaconda3/envs/ML_M1/lib/python3.9/site-packages/wandb/sdk/internal/internal_api.py", line 1001, in sweep
    response = self.gql(
  File "/Users/michalchrzanowski/anaconda3/envs/ML_M1/lib/python3.9/site-packages/wandb/sdk/internal/internal_api.py", line 338, in gql
    ret = self._retry_gql(
  File "/Users/michalchrzanowski/anaconda3/envs/ML_M1/lib/python3.9/site-packages/wandb/sdk/lib/retry.py", line 131, in __call__
    result = self._call_fn(*args, **kwargs)
  File "/Users/michalchrzanowski/anaconda3/envs/ML_M1/lib/python3.9/site-packages/wandb/sdk/internal/internal_api.py", line 366, in execute
    return self.client.execute(*args, **kwargs)  # type: ignore
  File "/Users/michalchrzanowski/anaconda3/envs/ML_M1/lib/python3.9/site-packages/wandb/vendor/gql-0.2.0/wandb_gql/client.py", line 52, in execute
    result = self._get_result(document, *args, **kwargs)
  File "/Users/michalchrzanowski/anaconda3/envs/ML_M1/lib/python3.9/site-packages/wandb/vendor/gql-0.2.0/wandb_gql/client.py", line 60, in _get_result
    return self.transport.execute(document, *args, **kwargs)
  File "/Users/michalchrzanowski/anaconda3/envs/ML_M1/lib/python3.9/site-packages/wandb/sdk/lib/gql_request.py", line 59, in execute
    request.raise_for_status()
  File "/Users/michalchrzanowski/anaconda3/envs/ML_M1/lib/python3.9/site-packages/requests/models.py", line 1021, in raise_for_status
    raise HTTPError(http_error_msg, response=self)
requests.exceptions.HTTPError: 400 Client Error: Bad Request for url: https://api.wandb.ai/graphql

During handling of the above exception, another exception occurred:

Traceback (most recent call last):
  File "/Users/michalchrzanowski/anaconda3/envs/ML_M1/lib/python3.9/site-packages/wandb/cli/cli.py", line 102, in wrapper
    return func(*args, **kwargs)
  File "/Users/michalchrzanowski/anaconda3/envs/ML_M1/lib/python3.9/site-packages/wandb/cli/cli.py", line 1496, in agent
    wandb_agent.agent(sweep_id, entity=entity, project=project, count=count)
  File "/Users/michalchrzanowski/anaconda3/envs/ML_M1/lib/python3.9/site-packages/wandb/wandb_agent.py", line 583, in agent
    return run_agent(
  File "/Users/michalchrzanowski/anaconda3/envs/ML_M1/lib/python3.9/site-packages/wandb/wandb_agent.py", line 528, in run_agent
    agent.run()
  File "/Users/michalchrzanowski/anaconda3/envs/ML_M1/lib/python3.9/site-packages/wandb/wandb_agent.py", line 190, in run
    sweep_obj = self._api.sweep(self._sweep_id, "{}")
  File "/Users/michalchrzanowski/anaconda3/envs/ML_M1/lib/python3.9/site-packages/wandb/apis/internal.py", line 126, in sweep
    return self.api.sweep(*args, **kwargs)
  File "/Users/michalchrzanowski/anaconda3/envs/ML_M1/lib/python3.9/site-packages/wandb/apis/normalize.py", line 51, in wrapper
    raise CommError(message, error)
wandb.errors.CommError: entityName required for project query (Error 400: Bad Request)

2023-11-06 19:56:47 INFO Running runs: []
2023-11-06 19:56:47 INFO Agent received command: run
2023-11-06 19:56:47 INFO Agent starting run with config:
	learning_rate: 0.01494200040812939
2023-11-06 19:56:47 INFO About to run command: /usr/bin/env python main.py --learning_rate=0.01494200040812939
2023-11-06 19:56:52 INFO Running runs: ['dl1ufbpa']
2023-11-06 19:56:52 INFO Cleaning up finished run: dl1ufbpa
2023-11-06 19:56:53 INFO Agent received command: run
2023-11-06 19:56:53 INFO Agent starting run with config:
	learning_rate: 0.04394369554099546
2023-11-06 19:56:53 INFO About to run command: /usr/bin/env python main.py --learning_rate=0.04394369554099546
2023-11-06 19:56:58 INFO Running runs: ['q2a2vqld']
2023-11-06 19:56:58 INFO Cleaning up finished run: q2a2vqld
2023-11-06 19:56:58 INFO Agent received command: run
2023-11-06 19:56:58 INFO Agent starting run with config:
	learning_rate: 0.024817065284334444
2023-11-06 19:56:58 INFO About to run command: /usr/bin/env python main.py --learning_rate=0.024817065284334444
2023-11-06 19:58:04 INFO Running runs: []
2023-11-06 19:58:05 INFO Agent received command: run
2023-11-06 19:58:05 INFO Agent starting run with config:
	learning_rate: 0.03052999034295172
2023-11-06 19:58:05 INFO About to run command: /usr/bin/env python main.py --learning_rate=0.03052999034295172
2023-11-06 19:58:10 INFO Running runs: ['b7dnf3d4']
2023-11-06 19:58:10 INFO Cleaning up finished run: b7dnf3d4
2023-11-06 19:58:11 INFO Agent received command: run
2023-11-06 19:58:11 INFO Agent starting run with config:
	learning_rate: 0.027563797947167987
2023-11-06 19:58:11 INFO About to run command: /usr/bin/env python main.py --learning_rate=0.027563797947167987
2023-11-06 19:58:16 INFO Running runs: ['tyim0ypu']
2023-11-06 19:58:16 INFO Cleaning up finished run: tyim0ypu
2023-11-06 19:58:16 INFO Agent received command: run
2023-11-06 19:58:16 INFO Agent starting run with config:
	learning_rate: 0.07362559409656902
2023-11-06 19:58:16 INFO About to run command: /usr/bin/env python main.py --learning_rate=0.07362559409656902
2023-11-06 19:59:28 INFO Running runs: []
2023-11-06 19:59:28 INFO Agent received command: run
2023-11-06 19:59:28 INFO Agent starting run with config:
	learning_rate: 0.008726761590121115
2023-11-06 19:59:28 INFO About to run command: /usr/bin/env python main.py --learning_rate=0.008726761590121115
2023-11-06 19:59:34 INFO Running runs: ['3yyl9zuz']
2023-11-06 19:59:39 INFO Cleaning up finished run: 3yyl9zuz
2023-11-06 19:59:45 INFO Agent received command: run
2023-11-06 19:59:45 INFO Agent starting run with config:
	learning_rate: 0.057602170631765835
2023-11-06 19:59:45 INFO About to run command: /usr/bin/env python main.py --learning_rate=0.057602170631765835
2023-11-06 19:59:50 INFO Running runs: ['7l19enif']
2023-11-06 20:00:34 INFO Running runs: []
2023-11-06 20:00:34 INFO Agent received command: run
2023-11-06 20:00:34 INFO Agent starting run with config:
	learning_rate: 0.06258654931758428
2023-11-06 20:00:34 INFO About to run command: /usr/bin/env python main.py --learning_rate=0.06258654931758428
2023-11-06 20:00:39 INFO Running runs: ['9s74a50b']
2023-11-06 20:00:45 INFO Cleaning up finished run: 9s74a50b
2023-11-06 20:04:56 INFO Running runs: []
2023-11-06 20:04:56 INFO Agent received command: run
2023-11-06 20:04:56 INFO Agent starting run with config:
	learning_rate: 0.04088501936979054
2023-11-06 20:04:56 INFO About to run command: /usr/bin/env python main.py --learning_rate=0.04088501936979054
2023-11-06 20:05:01 INFO Running runs: ['yedldm43']
2023-11-06 20:05:23 ERROR Traceback (most recent call last):
  File "/Users/michalchrzanowski/anaconda3/envs/ML_M1/lib/python3.9/site-packages/wandb/apis/normalize.py", line 41, in wrapper
    return func(*args, **kwargs)
  File "/Users/michalchrzanowski/anaconda3/envs/ML_M1/lib/python3.9/site-packages/wandb/sdk/internal/internal_api.py", line 2932, in upsert_sweep
    config = self._validate_config_and_fill_distribution(config)
  File "/Users/michalchrzanowski/anaconda3/envs/ML_M1/lib/python3.9/site-packages/wandb/sdk/internal/internal_api.py", line 2819, in _validate_config_and_fill_distribution
    if "min" in parameter and "max" in parameter:
TypeError: argument of type 'int' is not iterable

During handling of the above exception, another exception occurred:

Traceback (most recent call last):
  File "/Users/michalchrzanowski/anaconda3/envs/ML_M1/lib/python3.9/site-packages/wandb/cli/cli.py", line 102, in wrapper
    return func(*args, **kwargs)
  File "/Users/michalchrzanowski/anaconda3/envs/ML_M1/lib/python3.9/site-packages/wandb/cli/cli.py", line 841, in sweep
    sweep_id, warnings = api.upsert_sweep(
  File "/Users/michalchrzanowski/anaconda3/envs/ML_M1/lib/python3.9/site-packages/wandb/apis/internal.py", line 129, in upsert_sweep
    return self.api.upsert_sweep(*args, **kwargs)
  File "/Users/michalchrzanowski/anaconda3/envs/ML_M1/lib/python3.9/site-packages/wandb/apis/normalize.py", line 87, in wrapper
    raise CommError(message, err).with_traceback(sys.exc_info()[2])
  File "/Users/michalchrzanowski/anaconda3/envs/ML_M1/lib/python3.9/site-packages/wandb/apis/normalize.py", line 41, in wrapper
    return func(*args, **kwargs)
  File "/Users/michalchrzanowski/anaconda3/envs/ML_M1/lib/python3.9/site-packages/wandb/sdk/internal/internal_api.py", line 2932, in upsert_sweep
    config = self._validate_config_and_fill_distribution(config)
  File "/Users/michalchrzanowski/anaconda3/envs/ML_M1/lib/python3.9/site-packages/wandb/sdk/internal/internal_api.py", line 2819, in _validate_config_and_fill_distribution
    if "min" in parameter and "max" in parameter:
wandb.errors.CommError: argument of type 'int' is not iterable

2023-11-06 20:06:33 ERROR 400 response executing GraphQL.
2023-11-06 20:06:33 ERROR {"errors":[{"message":"Invalid sweep config: invalid hyperparameter configuration: epoch_num","path":["upsertSweep"]}],"data":{"upsertSweep":null}}
2023-11-06 20:06:33 ERROR Traceback (most recent call last):
  File "/Users/michalchrzanowski/anaconda3/envs/ML_M1/lib/python3.9/site-packages/wandb/sdk/lib/retry.py", line 131, in __call__
    result = self._call_fn(*args, **kwargs)
  File "/Users/michalchrzanowski/anaconda3/envs/ML_M1/lib/python3.9/site-packages/wandb/sdk/internal/internal_api.py", line 366, in execute
    return self.client.execute(*args, **kwargs)  # type: ignore
  File "/Users/michalchrzanowski/anaconda3/envs/ML_M1/lib/python3.9/site-packages/wandb/vendor/gql-0.2.0/wandb_gql/client.py", line 52, in execute
    result = self._get_result(document, *args, **kwargs)
  File "/Users/michalchrzanowski/anaconda3/envs/ML_M1/lib/python3.9/site-packages/wandb/vendor/gql-0.2.0/wandb_gql/client.py", line 60, in _get_result
    return self.transport.execute(document, *args, **kwargs)
  File "/Users/michalchrzanowski/anaconda3/envs/ML_M1/lib/python3.9/site-packages/wandb/sdk/lib/gql_request.py", line 59, in execute
    request.raise_for_status()
  File "/Users/michalchrzanowski/anaconda3/envs/ML_M1/lib/python3.9/site-packages/requests/models.py", line 1021, in raise_for_status
    raise HTTPError(http_error_msg, response=self)
requests.exceptions.HTTPError: 400 Client Error: Bad Request for url: https://api.wandb.ai/graphql

During handling of the above exception, another exception occurred:

Traceback (most recent call last):
  File "/Users/michalchrzanowski/anaconda3/envs/ML_M1/lib/python3.9/site-packages/wandb/cli/cli.py", line 102, in wrapper
    return func(*args, **kwargs)
  File "/Users/michalchrzanowski/anaconda3/envs/ML_M1/lib/python3.9/site-packages/wandb/cli/cli.py", line 841, in sweep
    sweep_id, warnings = api.upsert_sweep(
  File "/Users/michalchrzanowski/anaconda3/envs/ML_M1/lib/python3.9/site-packages/wandb/apis/internal.py", line 129, in upsert_sweep
    return self.api.upsert_sweep(*args, **kwargs)
  File "/Users/michalchrzanowski/anaconda3/envs/ML_M1/lib/python3.9/site-packages/wandb/apis/normalize.py", line 73, in wrapper
    raise err
  File "/Users/michalchrzanowski/anaconda3/envs/ML_M1/lib/python3.9/site-packages/wandb/apis/normalize.py", line 41, in wrapper
    return func(*args, **kwargs)
  File "/Users/michalchrzanowski/anaconda3/envs/ML_M1/lib/python3.9/site-packages/wandb/sdk/internal/internal_api.py", line 2960, in upsert_sweep
    raise e
  File "/Users/michalchrzanowski/anaconda3/envs/ML_M1/lib/python3.9/site-packages/wandb/sdk/internal/internal_api.py", line 2954, in upsert_sweep
    response = self.gql(
  File "/Users/michalchrzanowski/anaconda3/envs/ML_M1/lib/python3.9/site-packages/wandb/sdk/internal/internal_api.py", line 338, in gql
    ret = self._retry_gql(
  File "/Users/michalchrzanowski/anaconda3/envs/ML_M1/lib/python3.9/site-packages/wandb/sdk/lib/retry.py", line 147, in __call__
    retry_timedelta_triggered = check_retry_fn(e)
  File "/Users/michalchrzanowski/anaconda3/envs/ML_M1/lib/python3.9/site-packages/wandb/util.py", line 877, in no_retry_4xx
    raise UsageError(body["errors"][0]["message"])
wandb.errors.UsageError: Invalid sweep config: invalid hyperparameter configuration: epoch_num

2023-11-06 20:07:03 INFO Running runs: []
2023-11-06 20:07:04 INFO Agent received command: run
2023-11-06 20:07:04 INFO Agent starting run with config:
	epoch_num: 1
	learning_rate: 0.0015466544669408037
2023-11-06 20:07:04 INFO About to run command: /usr/bin/env python "main.py -sw" --epoch_num=1 --learning_rate=0.0015466544669408037
2023-11-06 20:07:09 INFO Running runs: ['l8iowynu']
2023-11-06 20:07:09 INFO Cleaning up finished run: l8iowynu
2023-11-06 20:07:09 INFO Agent received command: run
2023-11-06 20:07:09 INFO Agent starting run with config:
	epoch_num: 1
	learning_rate: 0.007319856509581157
2023-11-06 20:07:09 INFO About to run command: /usr/bin/env python "main.py -sw" --epoch_num=1 --learning_rate=0.007319856509581157
2023-11-06 20:07:14 INFO Running runs: ['539vaq68']
2023-11-06 20:07:14 INFO Cleaning up finished run: 539vaq68
2023-11-06 20:07:15 INFO Agent received command: run
2023-11-06 20:07:15 INFO Agent starting run with config:
	epoch_num: 1
	learning_rate: 0.008302802579062728
2023-11-06 20:07:15 INFO About to run command: /usr/bin/env python "main.py -sw" --epoch_num=1 --learning_rate=0.008302802579062728
2023-11-06 20:07:20 INFO Running runs: ['5xcgyynx']
2023-11-06 20:07:20 ERROR Detected 3 failed runs in the first 60 seconds, shutting down.
2023-11-06 20:07:20 INFO To disable this check set WANDB_AGENT_DISABLE_FLAPPING=true
2023-11-06 20:09:05 INFO Running runs: []
2023-11-06 20:09:05 INFO Agent received command: run
2023-11-06 20:09:05 INFO Agent starting run with config:
	epoch_num: 1
	learning_rate: 0.00489098047566455
2023-11-06 20:09:05 INFO About to run command: /usr/bin/env python main.py --epoch_num=1 --learning_rate=0.00489098047566455
2023-11-06 20:09:10 INFO Running runs: ['uycq3t5v']
2023-11-06 20:09:15 INFO Cleaning up finished run: uycq3t5v
2023-11-06 20:09:21 INFO Agent received command: run
2023-11-06 20:09:21 INFO Agent starting run with config:
	epoch_num: 1
	learning_rate: 0.0005605894120180301
2023-11-06 20:09:21 INFO About to run command: /usr/bin/env python main.py --epoch_num=1 --learning_rate=0.0005605894120180301
